Workbook

Sheet Data
A1: Date | B1: BoE 3Y OIS (%) | C1: BoE 3Y implied real spot (%) | D1: BoE 3Y Spot (%) | E1: BoE 10Y Spot (%) | F1: BoE 20Y Spot (%) | G1: Interpolated 5.56Y Yield (%) | H1: iShares Core £ Corp Bond (SLXX) (%) | I1: iShares Global HY Corp Bond ETF GBP Hedged (GHYS.L) (%) | J1: S&P 500 Price | K1: S&P 500 Returns (%) | L1: S&P 500 Earnings | M1: S&P 500 E/P | N1: Effective Federal Funds Rate (monthly) (%) | O1: Asset Returns (%) | P1: Slope (20Y-3Y) (%) | Q1: Butterfly (2x10Y-20Y-3Y) (%) | R1: Average SONIA (%) | S1: SONIA - EFFR (%) | T1: 3Y Gilt - 3Y OIS (%) | U1: Slope Change (%) | V1: Butterfly Change (%) | W1: IG Credit Spread (%) | X1: HY-IG Spread (%) | Y1: S&P 500 Returns - HY (%) | Z1: Inflation (3Y gilt - 3Y IL) (%) | AA1: Inflation Change (%) | AB1: VIX (Close) | AC1: Change in VIX (%) | AD1: S&P 500 ERP GBP Hedged (%)
A2: 41426 | B2: 0.052583709 | C2: -0.13666667 | D2: 0.060833333 | E2: 0.21833333 | F2: 0.29416667 | G2: =0.3657*E2+(1-0.3657)*D2 -> 0.11843108 | H2: -5.0202884 | I2: 0.92171578 | J2: 1618.77 | K2: =AVERAGE(K3:K145) -> 0.010751403 | L2: 90.95 | M2: =L2/J2 -> 0.056184634 | N2: 0.0075 | O2: -3.1231512 | P2: =F2-D2 -> 0.23333333 | Q2: =2*E2-F2-D2 -> 0.081666667 | R2: 0.035433333 | S2: =R2-N2 -> 0.027933333 | T2: =D2-B2 -> 0.0082496246 | U2: =AVERAGE(U3:U145) -> -0.00074009324 | V2: =AVERAGE(V3:V145) -> -0.00046037296 | W2: =H2-G2 -> -5.1387194 | X2: =I2-H2 -> 5.9420041 | Y2: =K2-I2 -> -0.91096438 | Z2: =D2-C2 -> 0.1975 | AA2: =AVERAGE(AA3:AA145) -> 0.00036713287 | AB2: 16.86 | AC2: 3.5626536 | AD2: =M2-N2 -> 0.048684634
A3: 41456 | B3: 0.044828492 | C3: -0.1675 | D3: 0.05 | E3: 0.21333333 | F3: 0.295 | G3: =0.3657*E3+(1-0.3657)*D3 -> 0.109731 | H3: 2.4581801 | I3: 2.4288457 | J3: 1668.68 | K3: =-1+J3/J2 -> 0.030832051 | L3: =L2*2/3+L5/3 -> 92.09 | M3: =L3/J3 -> 0.055187334 | N3: 0.0075 | O3: 3.4388142 | P3: =F3-D3 -> 0.245 | Q3: =2*E3-F3-D3 -> 0.081666667 | R3: 0.035841667 | S3: =R3-N3 -> 0.028341667 | T3: =D3-B3 -> 0.0051715084 | U3: =P3-P2 -> 0.011666667 | V3: =Q3-Q2 -> 0 | W3: =H3-G3 -> 2.3484491 | X3: =I3-H3 -> -0.029334478 | Y3: =K3-I3 -> -2.3980136 | Z3: =D3-C3 -> 0.2175 | AA3: =Z3-Z2 -> 0.02 | AB3: 13.45 | AC3: -16.975309 | AD3: =M3-N3 -> 0.047687334
A4: 41487 | B4: 0.064357428 | C4: -0.15833333 | D4: 0.069166667 | E4: 0.23583333 | F4: 0.30333333 | G4: =0.3657*E4+(1-0.3657)*D4 -> 0.13011667 | H4: -0.79307812 | I4: -0.74915777 | J4: 1670.09 | K4: =-1+J4/J3 -> 0.00084497927 | L4: =L2/3+L5*2/3 -> 93.23 | M4: =L4/J4 -> 0.055823339 | N4: 0.0066666667 | O4: -1.8423177 | P4: =F4-D4 -> 0.23416667 | Q4: =2*E4-F4-D4 -> 0.099166667 | R4: 0.035583333 | S4: =R4-N4 -> 0.028916667 | T4: =D4-B4 -> 0.0048092386 | U4: =P4-P3 -> -0.010833333 | V4: =Q4-Q3 -> 0.0175 | W4: =H4-G4 -> -0.92319479 | X4: =I4-H4 -> 0.04392035 | Y4: =K4-I4 -> 0.75000275 | Z4: =D4-C4 -> 0.2275 | AA4: =Z4-Z3 -> 0.01 | AB4: 17.01 | AC4: 43.665541 | AD4: =M4-N4 -> 0.049156672
A5: 41518 | B5: 0.067847311 | C5: -0.15666667 | D5: 0.071666667 | E5: 0.23 | F5: 0.295 | G5: =0.3657*E5+(1-0.3657)*D5 -> 0.12956917 | H5: 0.95391684 | I5: 1.2471351 | J5: 1687.17 | K5: =-1+J5/J4 -> 0.010226994 | L5: 94.37 | M5: =L5/J5 -> 0.055933901 | N5: 0.0066666667 | O5: 0.76476526 | P5: =F5-D5 -> 0.22333333 | Q5: =2*E5-F5-D5 -> 0.093333333 | R5: 0.035825 | S5: =R5-N5 -> 0.029158333 | T5: =D5-B5 -> 0.0038193557 | U5: =P5-P4 -> -0.010833333 | V5: =Q5-Q4 -> -0.0058333333 | W5: =H5-G5 -> 0.82434768 | X5: =I5-H5 -> 0.2932183 | Y5: =K5-I5 -> -1.2369081 | Z5: =D5-C5 -> 0.22833333 | AA5: =Z5-Z4 -> 0.00083333333 | AB5: 16.6 | AC5: -0.060204696 | AD5: =M5-N5 -> 0.049267234
A6: 41548 | B6: 0.064237813 | C6: -0.16666667 | D6: 0.069166667 | E6: 0.225 | F6: 0.29083333 | G6: =0.3657*E6+(1-0.3657)*D6 -> 0.12615492 | H6: 2.1513665 | I6: 2.4954859 | J6: 1720.03 | K6: =-1+J6/J5 -> 0.019476401 | L6: =L5*2/3+L8/3 -> 96.313333 | M6: =L6/J6 -> 0.055995147 | N6: 0.0075 | O6: 2.8438546 | P6: =F6-D6 -> 0.22166667 | Q6: =2*E6-F6-D6 -> 0.09 | R6: 0.035941667 | S6: =R6-N6 -> 0.028441667 | T6: =D6-B6 -> 0.004928854 | U6: =P6-P5 -> -0.0016666667 | V6: =Q6-Q5 -> -0.0033333333 | W6: =H6-G6 -> 2.0252116 | X6: =I6-H6 -> 0.34411937 | Y6: =K6-I6 -> -2.4760095 | Z6: =D6-C6 -> 0.23583333 | AA6: =Z6-Z5 -> 0.0075 | AB6: 13.75 | AC6: -17.86141 | AD6: =M6-N6 -> 0.048495147
A7: 41579 | B7: 0.067238377 | C7: -0.15333333 | D7: 0.075 | E7: 0.24 | F7: 0.30416667 | G7: =0.3657*E7+(1-0.3657)*D7 -> 0.1353405 | H7: -1.2729617 | I7: 0.038646518 | J7: 1783.54 | K7: =-1+J7/J6 -> 0.036923775 | L7: =L5/3+L8*2/3 -> 98.256667 | M7: =L7/J7 -> 0.055090812 | N7: 0.0066666667 | O7: -0.40587404 | P7: =F7-D7 -> 0.22916667 | Q7: =2*E7-F7-D7 -> 0.10083333 | R7: 0.035833333 | S7: =R7-N7 -> 0.029166667 | T7: =D7-B7 -> 0.007761623 | U7: =P7-P6 -> 0.0075 | V7: =Q7-Q6 -> 0.010833333 | W7: =H7-G7 -> -1.4083022 | X7: =I7-H7 -> 1.3116082 | Y7: =K7-I7 -> -0.0017227431 | Z7: =D7-C7 -> 0.22833333 | AA7: =Z7-Z6 -> -0.0075 | AB7: 13.7 | AC7: 3.1626506 | AD7: =M7-N7 -> 0.048424145
A8: 41609 | B8: 0.094568324 | C8: -0.14166667 | D8: 0.098333333 | E8: 0.26333333 | F8: 0.31083333 | G8: =0.3657*E8+(1-0.3657)*D8 -> 0.15867383 | H8: -0.73664307 | I8: 0.74090576 | J8: 1807.78 | K8: =-1+J8/J7 -> 0.013590948 | L8: 100.2 | M8: =L8/J8 -> 0.055427098 | N8: 0.0075 | O8: 0.3946379 | P8: =F8-D8 -> 0.2125 | Q8: =2*E8-F8-D8 -> 0.1175 | R8: 0.035125 | S8: =R8-N8 -> 0.027625 | T8: =D8-B8 -> 0.0037650094 | U8: =P8-P7 -> -0.016666667 | V8: =Q8-Q7 -> 0.016666667 | W8: =H8-G8 -> -0.8953169 | X8: =I8-H8 -> 1.4775488 | Y8: =K8-I8 -> -0.72731482 | Z8: =D8-C8 -> 0.24 | AA8: =Z8-Z7 -> 0.011666667 | AB8: 13.72 | AC8: -5.7044674 | AD8: =M8-N8 -> 0.047927098
A9: 41640 | B9: 0.085721878 | C9: -0.13666667 | D9: 0.0875 | E9: 0.23583333 | F9: 0.29583333 | G9: =0.3657*E9+(1-0.3657)*D9 -> 0.1417455 | H9: 2.2263747 | I9: 0.52818166 | J9: 1822.36 | K9: =-1+J9/J8 -> 0.0080651407 | L9: =L8*2/3+L11/3 -> 100.41667 | M9: =L9/J9 -> 0.055102541 | N9: 0.0058333333 | O9: -0.84486748 | P9: =F9-D9 -> 0.20833333 | Q9: =2*E9-F9-D9 -> 0.088333333 | R9: 0.035725 | S9: =R9-N9 -> 0.029891667 | T9: =D9-B9 -> 0.0017781225 | U9: =P9-P8 -> -0.0041666667 | V9: =Q9-Q8 -> -0.029166667 | W9: =H9-G9 -> 2.0846292 | X9: =I9-H9 -> -1.698193 | Y9: =K9-I9 -> -0.52011652 | Z9: =D9-C9 -> 0.22416667 | AA9: =Z9-Z8 -> -0.015833333 | AB9: 18.41 | AC9: 33.793605 | AD9: =M9-N9 -> 0.049269208
A10: 41671 | B10: 0.089329439 | C10: -0.14416667 | D10: 0.089166667 | E10: 0.23833333 | F10: 0.29583333 | G10: =0.3657*E10+(1-0.3657)*D10 -> 0.14371692 | H10: 0.33187521 | I10: 1.9235566 | J10: 1817.04 | K10: =-1+J10/J9 -> -0.0029192915 | L10: =L8/3+L11*2/3 -> 100.63333 | M10: =L10/J10 -> 0.055383114 | N10: 0.0058333333 | O10: 2.1320616 | P10: =F10-D10 -> 0.20666667 | Q10: =2*E10-F10-D10 -> 0.091666667 | R10: 0.034975 | S10: =R10-N10 -> 0.029141667 | T10: =D10-B10 -> -0.00016277218 | U10: =P10-P9 -> -0.0016666667 | V10: =Q10-Q9 -> 0.0033333333 | W10: =H10-G10 -> 0.18815829 | X10: =I10-H10 -> 1.5916814 | Y10: =K10-I10 -> -1.9264759 | Z10: =D10-C10 -> 0.23333333 | AA10: =Z10-Z9 -> 0.0091666667 | AB10: 14 | AC10: -23.954373 | AD10: =M10-N10 -> 0.049549781
A11: 41699 | B11: 0.098214001 | C11: -0.13833333 | D11: 0.099166667 | E11: 0.23916667 | F11: 0.29583333 | G11: =0.3657*E11+(1-0.3657)*D11 -> 0.15036467 | H11: -0.15367518 | I11: 0.018661357 | J11: 1863.52 | K11: =-1+J11/J10 -> 0.025580064 | L11: 100.85 | M11: =L11/J11 -> 0.054118013 | N11: 0.0066666667 | O11: -0.4241401 | P11: =F11-D11 -> 0.19666667 | Q11: =2*E11-F11-D11 -> 0.083333333 | R11: 0.034658333 | S11: =R11-N11 -> 0.027991667 | T11: =D11-B11 -> 0.00095266584 | U11: =P11-P10 -> -0.01 | V11: =Q11-Q10 -> -0.0083333333 | W11: =H11-G11 -> -0.30403985 | X11: =I11-H11 -> 0.17233654 | Y11: =K11-I11 -> 0.0069187077 | Z11: =D11-C11 -> 0.2375 | AA11: =Z11-Z10 -> 0.0041666667 | AB11: 13.88 | AC11: -1.5602837 | AD11: =M11-N11 -> 0.047451347
A12: 41730 | B12: 0.10053544 | C12: -0.145 | D12: 0.1 | E12: 0.23416667 | F12: 0.29166667 | G12: =0.3657*E12+(1-0.3657)*D12 -> 0.14906475 | H12: 1.3714712 | I12: 0.65116083 | J12: 1864.26 | K12: =-1+J12/J11 -> 0.00039709797 | L12: =L11*2/3+L14/3 -> 101.60667 | M12: =L12/J12 -> 0.054502412 | N12: 0.0075 | O12: 0.74520035 | P12: =F12-D12 -> 0.19166667 | Q12: =2*E12-F12-D12 -> 0.076666667 | R12: 0.035166667 | S12: =R12-N12 -> 0.027666667 | T12: =D12-B12 -> -0.00053543916 | U12: =P12-P11 -> -0.005 | V12: =Q12-Q11 -> -0.0066666667 | W12: =H12-G12 -> 1.2224064 | X12: =I12-H12 -> -0.72031035 | Y12: =K12-I12 -> -0.65076373 | Z12: =D12-C12 -> 0.245 | AA12: =Z12-Z11 -> 0.0075 | AB12: 13.41 | AC12: 2.4446142 | AD12: =M12-N12 -> 0.047002412
A13: 41760 | B13: 0.10034889 | C13: -0.135 | D13: 0.098333333 | E13: 0.225 | F13: 0.28416667 | G13: =0.3657*E13+(1-0.3657)*D13 -> 0.14465533 | H13: 1.263466 | I13: 0.52857926 | J13: 1889.77 | K13: =-1+J13/J12 -> 0.013683714 | L13: =L11/3+L14*2/3 -> 102.36333 | M13: =L13/J13 -> 0.054167086 | N13: 0.0075 | O13: 1.3893836 | P13: =F13-D13 -> 0.18583333 | Q13: =2*E13-F13-D13 -> 0.0675 | R13: 0.035275 | S13: =R13-N13 -> 0.027775 | T13: =D13-B13 -> -0.0020155552 | U13: =P13-P12 -> -0.0058333333 | V13: =Q13-Q12 -> -0.0091666667 | W13: =H13-G13 -> 1.1188107 | X13: =I13-H13 -> -0.73488673 | Y13: =K13-I13 -> -0.51489555 | Z13: =D13-C13 -> 0.23333333 | AA13: =Z13-Z12 -> -0.011666667 | AB13: 11.4 | AC13: -11.696359 | AD13: =M13-N13 -> 0.046667086
A14: 41791 | B14: 0.12043899 | C14: -0.115 | D14: 0.11833333 | E14: 0.23416667 | F14: 0.2875 | G14: =0.3657*E14+(1-0.3657)*D14 -> 0.16069358 | H14: -0.2331738 | I14: 0.87980609 | J14: 1947.09 | K14: =-1+J14/J13 -> 0.030331733 | L14: 103.12 | M14: =L14/J14 -> 0.052961086 | N14: 0.0083333333 | O14: -0.15960421 | P14: =F14-D14 -> 0.16916667 | Q14: =2*E14-F14-D14 -> 0.0625 | R14: 0.035425 | S14: =R14-N14 -> 0.027091667 | T14: =D14-B14 -> -0.0021056525 | U14: =P14-P13 -> -0.016666667 | V14: =Q14-Q13 -> -0.005 | W14: =H14-G14 -> -0.39386739 | X14: =I14-H14 -> 1.1129799 | Y14: =K14-I14 -> -0.84947435 | Z14: =D14-C14 -> 0.23333333 | AA14: =Z14-Z13 -> 0 | AB14: 11.57 | AC14: -2.5273799 | AD14: =M14-N14 -> 0.044627752
A15: 41821 | B15: 0.12138223 | C15: -0.11333333 | D15: 0.11916667 | E15: 0.23 | F15: 0.27666667 | G15: =0.3657*E15+(1-0.3657)*D15 -> 0.15969842 | H15: 0.39169156 | I15: -1.3143737 | J15: 1973.1 | K15: =-1+J15/J14 -> 0.013358396 | L15: =L14*2/3+L17/3 -> 104.06667 | M15: =L15/J15 -> 0.052742723 | N15: 0.0075 | O15: 0.0021744398 | P15: =F15-D15 -> 0.1575 | Q15: =2*E15-F15-D15 -> 0.064166667 | R15: 0.035691667 | S15: =R15-N15 -> 0.028191667 | T15: =D15-B15 -> -0.0022155666 | U15: =P15-P14 -> -0.011666667 | V15: =Q15-Q14 -> 0.0016666667 | W15: =H15-G15 -> 0.23199315 | X15: =I15-H15 -> -1.7060652 | Y15: =K15-I15 -> 1.3277321 | Z15: =D15-C15 -> 0.2325 | AA15: =Z15-Z14 -> -0.00083333333 | AB15: 16.95 | AC15: 64.244186 | AD15: =M15-N15 -> 0.045242723
A16: 41852 | B16: 0.10415775 | C16: -0.135 | D16: 0.10166667 | E16: 0.19916667 | F16: 0.2475 | G16: =0.3657*E16+(1-0.3657)*D16 -> 0.13732242 | H16: 3.1883543 | I16: 1.3564338 | J16: 1961.53 | K16: =-1+J16/J15 -> -0.005863869 | L16: =L14/3+L17*2/3 -> 105.01333 | M16: =L16/J16 -> 0.05353644 | N16: 0.0075 | O16: 2.1528111 | P16: =F16-D16 -> 0.14583333 | Q16: =2*E16-F16-D16 -> 0.049166667 | R16: 0.035233333 | S16: =R16-N16 -> 0.027733333 | T16: =D16-B16 -> -0.0024910871 | U16: =P16-P15 -> -0.011666667 | V16: =Q16-Q15 -> -0.015 | W16: =H16-G16 -> 3.0510319 | X16: =I16-H16 -> -1.8319205 | Y16: =K16-I16 -> -1.3622977 | Z16: =D16-C16 -> 0.23666667 | AA16: =Z16-Z15 -> 0.0041666667 | AB16: 11.98 | AC16: -20.767196 | AD16: =M16-N16 -> 0.04603644
A17: 41883 | B17: 0.10844735 | C17: -0.11666667 | D17: 0.10583333 | E17: 0.20583333 | F17: 0.255 | G17: =0.3657*E17+(1-0.3657)*D17 -> 0.14240333 | H17: -0.43329142 | I17: -1.7029454 | J17: 1993.23 | K17: =-1+J17/J16 -> 0.016160854 | L17: 105.96 | M17: =L17/J17 -> 0.053159946 | N17: 0.0075 | O17: -0.63321922 | P17: =F17-D17 -> 0.14916667 | Q17: =2*E17-F17-D17 -> 0.050833333 | R17: 0.035991667 | S17: =R17-N17 -> 0.028491667 | T17: =D17-B17 -> -0.0026140146 | U17: =P17-P16 -> 0.0033333333 | V17: =Q17-Q16 -> 0.0016666667 | W17: =H17-G17 -> -0.57569476 | X17: =I17-H17 -> -1.269654 | Y17: =K17-I17 -> 1.7191063 | Z17: =D17-C17 -> 0.2225 | AA17: =Z17-Z16 -> -0.014166667 | AB17: 16.31 | AC17: 31.957929 | AD17: =M17-N17 -> 0.045659946
A18: 41913 | B18: 0.091060826 | C18: -0.11583333 | D18: 0.088333333 | E18: 0.1925 | F18: 0.24833333 | G18: =0.3657*E18+(1-0.3657)*D18 -> 0.12642708 | H18: 0.47151302 | I18: 1.6125622 | J18: 1937.27 | K18: =-1+J18/J17 -> -0.028075034 | L18: =L17*2/3+L20/3 -> 104.74333 | M18: =L18/J18 -> 0.054067494 | N18: 0.0075 | O18: 0.5431128 | P18: =F18-D18 -> 0.16 | Q18: =2*E18-F18-D18 -> 0.048333333 | R18: 0.0359 | S18: =R18-N18 -> 0.0284 | T18: =D18-B18 -> -0.0027274931 | U18: =P18-P17 -> 0.010833333 | V18: =Q18-Q17 -> -0.0025 | W18: =H18-G18 -> 0.34508593 | X18: =I18-H18 -> 1.1410492 | Y18: =K18-I18 -> -1.6406373 | Z18: =D18-C18 -> 0.20416667 | AA18: =Z18-Z17 -> -0.018333333 | AB18: 14.03 | AC18: -9.2496766 | AD18: =M18-N18 -> 0.046567494
A19: 41944 | B19: 0.072590193 | C19: -0.1275 | D19: 0.070833333 | E19: 0.16583333 | F19: 0.22166667 | G19: =0.3657*E19+(1-0.3657)*D19 -> 0.10557483 | H19: 2.5724386 | I19: -0.45060331 | J19: 2044.57 | K19: =-1+J19/J18 -> 0.05538722 | L19: =L17/3+L20*2/3 -> 103.52667 | M19: =L19/J19 -> 0.050634934 | N19: 0.0075 | O19: 2.6535892 | P19: =F19-D19 -> 0.15083333 | Q19: =2*E19-F19-D19 -> 0.039166667 | R19: 0.036041667 | S19: =R19-N19 -> 0.028541667 | T19: =D19-B19 -> -0.00175686 | U19: =P19-P18 -> -0.0091666667 | V19: =Q19-Q18 -> -0.0091666667 | W19: =H19-G19 -> 2.4668638 | X19: =I19-H19 -> -3.0230419 | Y19: =K19-I19 -> 0.50599053 | Z19: =D19-C19 -> 0.19833333 | AA19: =Z19-Z18 -> -0.0058333333 | AB19: 13.33 | AC19: -4.9893086 | AD19: =M19-N19 -> 0.043134934
A20: 41974 | B20: 0.071621437 | C20: -0.13583333 | D20: 0.064166667 | E20: 0.15166667 | F20: 0.20666667 | G20: =0.3657*E20+(1-0.3657)*D20 -> 0.096165417 | H20: 1.4790637 | I20: -1.2777746 | J20: 2054.27 | K20: =-1+J20/J19 -> 0.0047442739 | L20: 102.31 | M20: =L20/J20 -> 0.04980358 | N20: 0.01 | O20: -0.1865194 | P20: =F20-D20 -> 0.1425 | Q20: =2*E20-F20-D20 -> 0.0325 | R20: 0.035666667 | S20: =R20-N20 -> 0.025666667 | T20: =D20-B20 -> -0.0074547702 | U20: =P20-P19 -> -0.0083333333 | V20: =Q20-Q19 -> -0.0066666667 | W20: =H20-G20 -> 1.3828983 | X20: =I20-H20 -> -2.7568383 | Y20: =K20-I20 -> 1.2825189 | Z20: =D20-C20 -> 0.2 | AA20: =Z20-Z19 -> 0.0016666667 | AB20: 19.2 | AC20: 53.969527 | AD20: =M20-N20 -> 0.03980358
A21: 42005 | B21: 0.057046471 | C21: -0.12 | D21: 0.05 | E21: 0.11583333 | F21: 0.1675 | G21: =0.3657*E21+(1-0.3657)*D21 -> 0.07407525 | H21: 6.0089659 | I21: 1.1830048 | J21: 2028.18 | K21: =-1+J21/J20 -> -0.012700375 | L21: =L20*2/3+L23/3 -> 101.29 | M21: =L21/J21 -> 0.049941327 | N21: 0.0091666667 | O21: 2.4047018 | P21: =F21-D21 -> 0.1175 | Q21: =2*E21-F21-D21 -> 0.014166667 | R21: 0.036291667 | S21: =R21-N21 -> 0.027125 | T21: =D21-B21 -> -0.0070464705 | U21: =P21-P20 -> -0.025 | V21: =Q21-Q20 -> -0.018333333 | W21: =H21-G21 -> 5.9348907 | X21: =I21-H21 -> -4.8259611 | Y21: =K21-I21 -> -1.1957052 | Z21: =D21-C21 -> 0.17 | AA21: =Z21-Z20 -> -0.03 | AB21: 20.97 | AC21: 17.875211 | AD21: =M21-N21 -> 0.04077466
A22: 42036 | B22: 0.079048727 | C22: -0.11583333 | D22: 0.071666667 | E22: 0.155 | F22: 0.205 | G22: =0.3657*E22+(1-0.3657)*D22 -> 0.10214167 | H22: -3.6375516 | I22: 2.0940891 | J22: 2082.2 | K22: =-1+J22/J21 -> 0.026634717 | L22: =L20/3+L23*2/3 -> 100.27 | M22: =L22/J22 -> 0.048155797 | N22: 0.0091666667 | O22: 0.82206753 | P22: =F22-D22 -> 0.13333333 | Q22: =2*E22-F22-D22 -> 0.033333333 | R22: 0.037591667 | S22: =R22-N22 -> 0.028425 | T22: =D22-B22 -> -0.0073820605 | U22: =P22-P21 -> 0.015833333 | V22: =Q22-Q21 -> 0.019166667 | W22: =H22-G22 -> -3.7396932 | X22: =I22-H22 -> 5.7316407 | Y22: =K22-I22 -> -2.0674544 | Z22: =D22-C22 -> 0.1875 | AA22: =Z22-Z21 -> 0.0175 | AB22: 13.34 | AC22: -36.385312 | AD22: =M22-N22 -> 0.03898913
A23: 42064 | B23: 0.064717583 | C23: -0.14416667 | D23: 0.055833333 | E23: 0.13833333 | F23: 0.19083333 | G23: =0.3657*E23+(1-0.3657)*D23 -> 0.086003583 | H23: 1.1854893 | I23: -0.77587498 | J23: 2079.99 | K23: =-1+J23/J22 -> -0.0010613774 | L23: 99.25 | M23: =L23/J23 -> 0.047716576 | N23: 0.0091666667 | O23: 0.79790761 | P23: =F23-D23 -> 0.135 | Q23: =2*E23-F23-D23 -> 0.03 | R23: 0.038066667 | S23: =R23-N23 -> 0.0289 | T23: =D23-B23 -> -0.0088842496 | U23: =P23-P22 -> 0.0016666667 | V23: =Q23-Q22 -> -0.0033333333 | W23: =H23-G23 -> 1.0994857 | X23: =I23-H23 -> -1.9613643 | Y23: =K23-I23 -> 0.7748136 | Z23: =D23-C23 -> 0.2 | AA23: =Z23-Z22 -> 0.0125 | AB23: 15.29 | AC23: 7.4490513 | AD23: =M23-N23 -> 0.038549909
A24: 42095 | B24: 0.075883935 | C24: -0.14666667 | D24: 0.07 | E24: 0.16166667 | F24: 0.21083333 | G24: =0.3657*E24+(1-0.3657)*D24 -> 0.1035225 | H24: -2.2229609 | I24: 0.65171916 | J24: 2094.86 | K24: =-1+J24/J23 -> 0.0071490728 | L24: =L23*2/3+L26/3 -> 97.803333 | M24: =L24/J24 -> 0.046687289 | N24: 0.01 | O24: -0.23417506 | P24: =F24-D24 -> 0.14083333 | Q24: =2*E24-F24-D24 -> 0.0425 | R24: 0.038116667 | S24: =R24-N24 -> 0.028116667 | T24: =D24-B24 -> -0.0058839348 | U24: =P24-P23 -> 0.0058333333 | V24: =Q24-Q23 -> 0.0125 | W24: =H24-G24 -> -2.3264834 | X24: =I24-H24 -> 2.8746801 | Y24: =K24-I24 -> -0.64457008 | Z24: =D24-C24 -> 0.21666667 | AA24: =Z24-Z23 -> 0.016666667 | AB24: 14.55 | AC24: -0.81799591 | AD24: =M24-N24 -> 0.036687289
A25: 42125 | B25: 0.073903398 | C25: -0.14083333 | D25: 0.0675 | E25: 0.16 | F25: 0.21083333 | G25: =0.3657*E25+(1-0.3657)*D25 -> 0.10132725 | H25: 0.37532703 | I25: -0.13018686 | J25: 2111.94 | K25: =-1+J25/J24 -> 0.0081532895 | L25: =L23/3+L26*2/3 -> 96.356667 | M25: =L25/J25 -> 0.045624718 | N25: 0.01 | O25: 0.4490633 | P25: =F25-D25 -> 0.14333333 | Q25: =2*E25-F25-D25 -> 0.041666667 | R25: 0.0385 | S25: =R25-N25 -> 0.0285 | T25: =D25-B25 -> -0.0064033976 | U25: =P25-P24 -> 0.0025 | V25: =Q25-Q24 -> -0.00083333333 | W25: =H25-G25 -> 0.27399978 | X25: =I25-H25 -> -0.5055139 | Y25: =K25-I25 -> 0.13834015 | Z25: =D25-C25 -> 0.20833333 | AA25: =Z25-Z24 -> -0.0083333333 | AB25: 13.84 | AC25: 8.976378 | AD25: =M25-N25 -> 0.035624718
A26: 42156 | B26: 0.086698665 | C26: -0.135 | D26: 0.08 | E26: 0.18 | F26: 0.22916667 | G26: =0.3657*E26+(1-0.3657)*D26 -> 0.11657 | H26: -3.6542343 | I26: -1.8355748 | J26: 2099.29 | K26: =-1+J26/J25 -> -0.0059897535 | L26: 94.91 | M26: =L26/J26 -> 0.045210524 | N26: 0.010833333 | O26: -3.3442886 | P26: =F26-D26 -> 0.14916667 | Q26: =2*E26-F26-D26 -> 0.050833333 | R26: 0.03805 | S26: =R26-N26 -> 0.027216667 | T26: =D26-B26 -> -0.0066986653 | U26: =P26-P25 -> 0.0058333333 | V26: =Q26-Q25 -> 0.0091666667 | W26: =H26-G26 -> -3.7708043 | X26: =I26-H26 -> 1.8186596 | Y26: =K26-I26 -> 1.829585 | Z26: =D26-C26 -> 0.215 | AA26: =Z26-Z25 -> 0.0066666667 | AB26: 18.23 | AC26: 33.455344 | AD26: =M26-N26 -> 0.03437719
A27: 42186 | B27: 0.087778972 | C27: -0.11833333 | D27: 0.079166667 | E27: 0.1675 | F27: 0.21583333 | G27: =0.3657*E27+(1-0.3657)*D27 -> 0.11147017 | H27: 2.5427263 | I27: 0.19396134 | J27: 2094.14 | K27: =-1+J27/J26 -> -0.0024532104 | L27: =L26*2/3+L29/3 -> 93.493333 | M27: =L27/J27 -> 0.044645216 | N27: 0.010833333 | O27: 1.9551601 | P27: =F27-D27 -> 0.13666667 | Q27: =2*E27-F27-D27 -> 0.04 | R27: 0.037908333 | S27: =R27-N27 -> 0.027075 | T27: =D27-B27 -> -0.0086123056 | U27: =P27-P26 -> -0.0125 | V27: =Q27-Q26 -> -0.010833333 | W27: =H27-G27 -> 2.4312561 | X27: =I27-H27 -> -2.3487649 | Y27: =K27-I27 -> -0.19641455 | Z27: =D27-C27 -> 0.1975 | AA27: =Z27-Z26 -> -0.0175 | AB27: 12.12 | AC27: -28.747795 | AD27: =M27-N27 -> 0.033811883
A28: 42217 | B28: 0.080176109 | C28: -0.10416667 | D28: 0.075 | E28: 0.16416667 | F28: 0.21666667 | G28: =0.3657*E28+(1-0.3657)*D28 -> 0.10760825 | H28: -2.0562685 | I28: -1.5737927 | J28: 2039.87 | K28: =-1+J28/J27 -> -0.025915173 | L28: =L26/3+L29*2/3 -> 92.076667 | M28: =L28/J28 -> 0.045138497 | N28: 0.011666667 | O28: -2.9682787 | P28: =F28-D28 -> 0.14166667 | Q28: =2*E28-F28-D28 -> 0.036666667 | R28: 0.03825 | S28: =R28-N28 -> 0.026583333 | T28: =D28-B28 -> -0.005176109 | U28: =P28-P27 -> 0.005 | V28: =Q28-Q27 -> -0.0033333333 | W28: =H28-G28 -> -2.1638767 | X28: =I28-H28 -> 0.48247579 | Y28: =K28-I28 -> 1.5478775 | Z28: =D28-C28 -> 0.17916667 | AA28: =Z28-Z27 -> -0.018333333 | AB28: 28.43 | AC28: 118.69231 | AD28: =M28-N28 -> 0.033471831
A29: 42248 | B29: 0.067917662 | C29: -0.12166667 | D29: 0.064166667 | E29: 0.14916667 | F29: 0.20916667 | G29: =0.3657*E29+(1-0.3657)*D29 -> 0.095251167 | H29: 0.59783704 | I29: -2.8866131 | J29: 1944.41 | K29: =-1+J29/J28 -> -0.0467971 | L29: 90.66 | M29: =L29/J29 -> 0.046625969 | N29: 0.011666667 | O29: -0.94912629 | P29: =F29-D29 -> 0.145 | Q29: =2*E29-F29-D29 -> 0.025 | R29: 0.037866667 | S29: =R29-N29 -> 0.0262 | T29: =D29-B29 -> -0.0037509955 | U29: =P29-P28 -> 0.0033333333 | V29: =Q29-Q28 -> -0.011666667 | W29: =H29-G29 -> 0.50258588 | X29: =I29-H29 -> -3.4844501 | Y29: =K29-I29 -> 2.839816 | Z29: =D29-C29 -> 0.18583333 | AA29: =Z29-Z28 -> 0.0066666667 | AB29: 24.5 | AC29: -6.094289 | AD29: =M29-N29 -> 0.034959302
A30: 42278 | B30: 0.072056751 | C30: -0.11583333 | D30: 0.070833333 | E30: 0.1625 | F30: 0.22083333 | G30: =0.3657*E30+(1-0.3657)*D30 -> 0.10435583 | H30: 0.11936853 | I30: 3.485803 | J30: 2024.81 | K30: =-1+J30/J29 -> 0.041349304 | L30: =L29*2/3+L32/3 -> 89.283333 | M30: =L30/J30 -> 0.044094672 | N30: 0.01 | O30: 2.6833913 | P30: =F30-D30 -> 0.15 | Q30: =2*E30-F30-D30 -> 0.033333333 | R30: 0.038516667 | S30: =R30-N30 -> 0.028516667 | T30: =D30-B30 -> -0.0012234181 | U30: =P30-P29 -> 0.005 | V30: =Q30-Q29 -> 0.0083333333 | W30: =H30-G30 -> 0.015012702 | X30: =I30-H30 -> 3.3664345 | Y30: =K30-I30 -> -3.4444537 | Z30: =D30-C30 -> 0.18666667 | AA30: =Z30-Z29 -> 0.00083333333 | AB30: 15.07 | AC30: -22.876151 | AD30: =M30-N30 -> 0.034094672
A31: 42309 | B31: 0.067605646 | C31: -0.12166667 | D31: 0.069166667 | E31: 0.15583333 | F31: 0.21583333 | G31: =0.3657*E31+(1-0.3657)*D31 -> 0.10086067 | H31: 2.1742913 | I31: -1.8790029 | J31: 2080.62 | K31: =-1+J31/J30 -> 0.02756308 | L31: =L29/3+L32*2/3 -> 87.906667 | M31: =L31/J31 -> 0.042250227 | N31: 0.01 | O31: 1.0849102 | P31: =F31-D31 -> 0.14666667 | Q31: =2*E31-F31-D31 -> 0.026666667 | R31: 0.038633333 | S31: =R31-N31 -> 0.028633333 | T31: =D31-B31 -> 0.0015610207 | U31: =P31-P30 -> -0.0033333333 | V31: =Q31-Q30 -> -0.0066666667 | W31: =H31-G31 -> 2.0734307 | X31: =I31-H31 -> -4.0532943 | Y31: =K31-I31 -> 1.906566 | Z31: =D31-C31 -> 0.19083333 | AA31: =Z31-Z30 -> 0.0041666667 | AB31: 16.13 | AC31: 13.992933 | AD31: =M31-N31 -> 0.032250227
A32: 42339 | B32: 0.0824033 | C32: -0.1 | D32: 0.079166667 | E32: 0.1675 | F32: 0.22583333 | G32: =0.3657*E32+(1-0.3657)*D32 -> 0.11147017 | H32: -1.3050321 | I32: -2.2541702 | J32: 2054.08 | K32: =-1+J32/J31 -> -0.012755813 | L32: 86.53 | M32: =L32/J32 -> 0.042125915 | N32: 0.02 | O32: -0.60205936 | P32: =F32-D32 -> 0.14666667 | Q32: =2*E32-F32-D32 -> 0.03 | R32: 0.038125 | S32: =R32-N32 -> 0.018125 | T32: =D32-B32 -> -0.0032366331 | U32: =P32-P31 -> 0 | V32: =Q32-Q31 -> 0.0033333333 | W32: =H32-G32 -> -1.4165022 | X32: =I32-H32 -> -0.94913814 | Y32: =K32-I32 -> 2.2414144 | Z32: =D32-C32 -> 0.17916667 | AA32: =Z32-Z31 -> -0.011666667 | AB32: 18.21 | AC32: 0.55218112 | AD32: =M32-N32 -> 0.022125915
A33: 42370 | B33: 0.047280347 | C33: -0.13083333 | D33: 0.046666667 | E33: 0.13666667 | F33: 0.19916667 | G33: =0.3657*E33+(1-0.3657)*D33 -> 0.079579667 | H33: 0.74773687 | I33: -1.6993921 | J33: 1918.6 | K33: =-1+J33/J32 -> -0.065956535 | L33: =L32*2/3+L35/3 -> 86.5 | M33: =L33/J33 -> 0.045084958 | N33: 0.028333333 | O33: -1.3845335 | P33: =F33-D33 -> 0.1525 | Q33: =2*E33-F33-D33 -> 0.0275 | R33: 0.038825 | S33: =R33-N33 -> 0.010491667 | T33: =D33-B33 -> -0.00061367997 | U33: =P33-P32 -> 0.0058333333 | V33: =Q33-Q32 -> -0.0025 | W33: =H33-G33 -> 0.66815721 | X33: =I33-H33 -> -2.447129 | Y33: =K33-I33 -> 1.6334355 | Z33: =D33-C33 -> 0.1775 | AA33: =Z33-Z32 -> -0.0016666667 | AB33: 20.2 | AC33: 10.928062 | AD33: =M33-N33 -> 0.016751624
A34: 42401 | B34: 0.02952729 | C34: -0.12083333 | D34: 0.031666667 | E34: 0.1175 | F34: 0.1925 | G34: =0.3657*E34+(1-0.3657)*D34 -> 0.063055917 | H34: -0.74469809 | I34: 0.79501459 | J34: 1904.42 | K34: =-1+J34/J33 -> -0.0073908058 | L34: =L32/3+L35*2/3 -> 86.47 | M34: =L34/J34 -> 0.0454049 | N34: 0.031666667 | O34: 0.51269215 | P34: =F34-D34 -> 0.16083333 | Q34: =2*E34-F34-D34 -> 0.010833333 | R34: 0.038808333 | S34: =R34-N34 -> 0.0071416667 | T34: =D34-B34 -> 0.0021393763 | U34: =P34-P33 -> 0.0083333333 | V34: =Q34-Q33 -> -0.016666667 | W34: =H34-G34 -> -0.80775401 | X34: =I34-H34 -> 1.5397127 | Y34: =K34-I34 -> -0.80240539 | Z34: =D34-C34 -> 0.1525 | AA34: =Z34-Z33 -> -0.025 | AB34: 20.55 | AC34: 2.8528529 | AD34: =M34-N34 -> 0.013738234
A35: 42430 | B35: 0.039134295 | C35: -0.15083333 | D35: 0.04 | E35: 0.125 | F35: 0.19333333 | G35: =0.3657*E35+(1-0.3657)*D35 -> 0.0710845 | H35: 3.6665013 | I35: 3.688794 | J35: 2021.95 | K35: =-1+J35/J34 -> 0.061714328 | L35: 86.44 | M35: =L35/J35 -> 0.04275081 | N35: 0.03 | O35: 2.1127325 | P35: =F35-D35 -> 0.15333333 | Q35: =2*E35-F35-D35 -> 0.016666667 | R35: 0.038716667 | S35: =R35-N35 -> 0.0087166667 | T35: =D35-B35 -> 0.00086570504 | U35: =P35-P34 -> -0.0075 | V35: =Q35-Q34 -> 0.0058333333 | W35: =H35-G35 -> 3.5954168 | X35: =I35-H35 -> 0.022292749 | Y35: =K35-I35 -> -3.6270797 | Z35: =D35-C35 -> 0.19083333 | AA35: =Z35-Z34 -> 0.038333333 | AB35: 13.95 | AC35: -16.467066 | AD35: =M35-N35 -> 0.01275081
A36: 42461 | B36: 0.049262317 | C36: -0.14583333 | D36: 0.050833333 | E36: 0.14083333 | F36: 0.20416667 | G36: =0.3657*E36+(1-0.3657)*D36 -> 0.083746333 | H36: 0.99565048 | I36: 2.3541004 | J36: 2075.54 | K36: =-1+J36/J35 -> 0.026504117 | L36: =L35*2/3+L38/3 -> 86.6 | M36: =L36/J36 -> 0.041724081 | N36: 0.030833333 | O36: 0.4466425 | P36: =F36-D36 -> 0.15333333 | Q36: =2*E36-F36-D36 -> 0.026666667 | R36: 0.038858333 | S36: =R36-N36 -> 0.008025 | T36: =D36-B36 -> 0.0015710166 | U36: =P36-P35 -> 0 | V36: =Q36-Q35 -> 0.01 | W36: =H36-G36 -> 0.91190414 | X36: =I36-H36 -> 1.3584499 | Y36: =K36-I36 -> -2.3275963 | Z36: =D36-C36 -> 0.19666667 | AA36: =Z36-Z35 -> 0.0058333333 | AB36: 15.7 | AC36: 11.189802 | AD36: =M36-N36 -> 0.010890748
A37: 42491 | B37: 0.048811821 | C37: -0.14166667 | D37: 0.046666667 | E37: 0.12916667 | F37: 0.19 | G37: =0.3657*E37+(1-0.3657)*D37 -> 0.076836917 | H37: 0.931525 | I37: 0.32928549 | J37: 2065.55 | K37: =-1+J37/J36 -> -0.0048132052 | L37: =L35/3+L38*2/3 -> 86.76 | M37: =L37/J37 -> 0.042003341 | N37: 0.030833333 | O37: 0.80909571 | P37: =F37-D37 -> 0.14333333 | Q37: =2*E37-F37-D37 -> 0.021666667 | R37: 0.038608333 | S37: =R37-N37 -> 0.007775 | T37: =D37-B37 -> -0.0021451548 | U37: =P37-P36 -> -0.01 | V37: =Q37-Q36 -> -0.005 | W37: =H37-G37 -> 0.85468808 | X37: =I37-H37 -> -0.60223951 | Y37: =K37-I37 -> -0.33409869 | Z37: =D37-C37 -> 0.18833333 | AA37: =Z37-Z36 -> -0.0083333333 | AB37: 14.19 | AC37: -9.0384615 | AD37: =M37-N37 -> 0.011170007
A38: 42522 | B38: 0.0089930273 | C38: -0.19333333 | D38: 0.0125 | E38: 0.085833333 | F38: 0.14916667 | G38: =0.3657*E38+(1-0.3657)*D38 -> 0.039318 | H38: 3.605795 | I38: 0.76956632 | J38: 2083.89 | K38: =-1+J38/J37 -> 0.0088789911 | L38: 86.92 | M38: =L38/J38 -> 0.041710455 | N38: 0.031666667 | O38: 3.3950819 | P38: =F38-D38 -> 0.13666667 | Q38: =2*E38-F38-D38 -> 0.01 | R38: 0.038316667 | S38: =R38-N38 -> 0.00665 | T38: =D38-B38 -> 0.0035069727 | U38: =P38-P37 -> -0.0066666667 | V38: =Q38-Q37 -> -0.011666667 | W38: =H38-G38 -> 3.566477 | X38: =I38-H38 -> -2.8362287 | Y38: =K38-I38 -> -0.76068732 | Z38: =D38-C38 -> 0.20583333 | AA38: =Z38-Z37 -> 0.0175 | AB38: 15.63 | AC38: 16.035635 | AD38: =M38-N38 -> 0.010043788
A39: 42552 | B39: 0.010781126 | C39: -0.21 | D39: 0.0075 | E39: 0.066666667 | F39: 0.13083333 | G39: =0.3657*E39+(1-0.3657)*D39 -> 0.02913725 | H39: 5.0756542 | I39: 2.3978115 | J39: 2148.9 | K39: =-1+J39/J38 -> 0.031196464 | L39: =L38*2/3+L41/3 -> 87.643333 | M39: =L39/J39 -> 0.040785208 | N39: 0.0325 | O39: 3.1095109 | P39: =F39-D39 -> 0.12333333 | Q39: =2*E39-F39-D39 -> -0.005 | R39: 0.038141667 | S39: =R39-N39 -> 0.0056416667 | T39: =D39-B39 -> -0.0032811258 | U39: =P39-P38 -> -0.013333333 | V39: =Q39-Q38 -> -0.015 | W39: =H39-G39 -> 5.046517 | X39: =I39-H39 -> -2.6778428 | Y39: =K39-I39 -> -2.366615 | Z39: =D39-C39 -> 0.2175 | AA39: =Z39-Z38 -> 0.011666667 | AB39: 11.87 | AC39: -19.634394 | AD39: =M39-N39 -> 0.0082852079
A40: 42583 | B40: 0.0090552495 | C40: -0.22583333 | D40: 0.0083333333 | E40: 0.055 | F40: 0.10666667 | G40: =0.3657*E40+(1-0.3657)*D40 -> 0.025399333 | H40: 3.4464466 | I40: 2.0430672 | J40: 2170.95 | K40: =-1+J40/J39 -> 0.010261064 | L40: =L38/3+L41*2/3 -> 88.366667 | M40: =L40/J40 -> 0.040704146 | N40: 0.033333333 | O40: 1.5752476 | P40: =F40-D40 -> 0.098333333 | Q40: =2*E40-F40-D40 -> -0.005 | R40: 0.02065 | S40: =R40-N40 -> -0.012683333 | T40: =D40-B40 -> -0.00072191616 | U40: =P40-P39 -> -0.025 | V40: =Q40-Q39 -> -8.6736174e-18 | W40: =H40-G40 -> 3.4210473 | X40: =I40-H40 -> -1.4033794 | Y40: =K40-I40 -> -2.0328062 | Z40: =D40-C40 -> 0.23416667 | AA40: =Z40-Z39 -> 0.016666667 | AB40: 13.42 | AC40: 8.0515298 | AD40: =M40-N40 -> 0.0073708131
...

Sheet Data for CSV Export
A1: date | B1: asset_returns | C1: SONIA | D1: SONIA_EFFR_spread | E1: slope | F1: slope_change | G1: butterfly | H1: butterfly_change | I1: swap_spread | J1: IG_gilt_spread | K1: HY_IG_spread | L1: inflation | M1: inflation_change | N1: S&P_500_HY_spread | O1: S&P_500_ERP | P1: VIX | Q1: VIX_change
A2: {=Data!A2:A145} -> 41426 | B2: {=Data!O2:O145} -> -3.1231512 | C2: {=Data!R2:R145} -> 0.035433333 | D2: {=Data!S2:S145} -> 0.027933333 | E2: {=Data!P2:P145} -> 0.23333333 | F2: {=Data!U2:U145} -> -0.00074009324 | G2: {=Data!Q2:Q145} -> 0.081666667 | H2: {=Data!V2:V145} -> -0.00046037296 | I2: {=Data!T2:T145} -> 0.0082496246 | J2: {=Data!W2:W145} -> -5.1387194 | K2: {=Data!X2:X145} -> 5.9420041 | L2: {=Data!Z2:Z145} -> 0.1975 | M2: {=Data!AA2:AA145} -> 0.00036713287 | N2: {=Data!Y2:Y145} -> -0.91096438 | O2: {=Data!AD2:AD145} -> 0.048684634 | P2: {=Data!AB2:AB145} -> 16.86 | Q2: {=Data!AC2:AC145} -> 3.5626536
A3: 41456 | B3: 3.4388142 | C3: 0.035841667 | D3: 0.028341667 | E3: 0.245 | F3: 0.011666667 | G3: 0.081666667 | H3: 0 | I3: 0.0051715084 | J3: 2.3484491 | K3: -0.029334478 | L3: 0.2175 | M3: 0.02 | N3: -2.3980136 | O3: 0.047687334 | P3: 13.45 | Q3: -16.975309
A4: 41487 | B4: -1.8423177 | C4: 0.035583333 | D4: 0.028916667 | E4: 0.23416667 | F4: -0.010833333 | G4: 0.099166667 | H4: 0.0175 | I4: 0.0048092386 | J4: -0.92319479 | K4: 0.04392035 | L4: 0.2275 | M4: 0.01 | N4: 0.75000275 | O4: 0.049156672 | P4: 17.01 | Q4: 43.665541
A5: 41518 | B5: 0.76476526 | C5: 0.035825 | D5: 0.029158333 | E5: 0.22333333 | F5: -0.010833333 | G5: 0.093333333 | H5: -0.0058333333 | I5: 0.0038193557 | J5: 0.82434768 | K5: 0.2932183 | L5: 0.22833333 | M5: 0.00083333333 | N5: -1.2369081 | O5: 0.049267234 | P5: 16.6 | Q5: -0.060204696
A6: 41548 | B6: 2.8438546 | C6: 0.035941667 | D6: 0.028441667 | E6: 0.22166667 | F6: -0.0016666667 | G6: 0.09 | H6: -0.0033333333 | I6: 0.004928854 | J6: 2.0252116 | K6: 0.34411937 | L6: 0.23583333 | M6: 0.0075 | N6: -2.4760095 | O6: 0.048495147 | P6: 13.75 | Q6: -17.86141
A7: 41579 | B7: -0.40587404 | C7: 0.035833333 | D7: 0.029166667 | E7: 0.22916667 | F7: 0.0075 | G7: 0.10083333 | H7: 0.010833333 | I7: 0.007761623 | J7: -1.4083022 | K7: 1.3116082 | L7: 0.22833333 | M7: -0.0075 | N7: -0.0017227431 | O7: 0.048424145 | P7: 13.7 | Q7: 3.1626506
A8: 41609 | B8: 0.3946379 | C8: 0.035125 | D8: 0.027625 | E8: 0.2125 | F8: -0.016666667 | G8: 0.1175 | H8: 0.016666667 | I8: 0.0037650094 | J8: -0.8953169 | K8: 1.4775488 | L8: 0.24 | M8: 0.011666667 | N8: -0.72731482 | O8: 0.047927098 | P8: 13.72 | Q8: -5.7044674
A9: 41640 | B9: -0.84486748 | C9: 0.035725 | D9: 0.029891667 | E9: 0.20833333 | F9: -0.0041666667 | G9: 0.088333333 | H9: -0.029166667 | I9: 0.0017781225 | J9: 2.0846292 | K9: -1.698193 | L9: 0.22416667 | M9: -0.015833333 | N9: -0.52011652 | O9: 0.049269208 | P9: 18.41 | Q9: 33.793605
A10: 41671 | B10: 2.1320616 | C10: 0.034975 | D10: 0.029141667 | E10: 0.20666667 | F10: -0.0016666667 | G10: 0.091666667 | H10: 0.0033333333 | I10: -0.00016277218 | J10: 0.18815829 | K10: 1.5916814 | L10: 0.23333333 | M10: 0.0091666667 | N10: -1.9264759 | O10: 0.049549781 | P10: 14 | Q10: -23.954373
A11: 41699 | B11: -0.4241401 | C11: 0.034658333 | D11: 0.027991667 | E11: 0.19666667 | F11: -0.01 | G11: 0.083333333 | H11: -0.0083333333 | I11: 0.00095266584 | J11: -0.30403985 | K11: 0.17233654 | L11: 0.2375 | M11: 0.0041666667 | N11: 0.0069187077 | O11: 0.047451347 | P11: 13.88 | Q11: -1.5602837
A12: 41730 | B12: 0.74520035 | C12: 0.035166667 | D12: 0.027666667 | E12: 0.19166667 | F12: -0.005 | G12: 0.076666667 | H12: -0.0066666667 | I12: -0.00053543916 | J12: 1.2224064 | K12: -0.72031035 | L12: 0.245 | M12: 0.0075 | N12: -0.65076373 | O12: 0.047002412 | P12: 13.41 | Q12: 2.4446142
A13: 41760 | B13: 1.3893836 | C13: 0.035275 | D13: 0.027775 | E13: 0.18583333 | F13: -0.0058333333 | G13: 0.0675 | H13: -0.0091666667 | I13: -0.0020155552 | J13: 1.1188107 | K13: -0.73488673 | L13: 0.23333333 | M13: -0.011666667 | N13: -0.51489555 | O13: 0.046667086 | P13: 11.4 | Q13: -11.696359
A14: 41791 | B14: -0.15960421 | C14: 0.035425 | D14: 0.027091667 | E14: 0.16916667 | F14: -0.016666667 | G14: 0.0625 | H14: -0.005 | I14: -0.0021056525 | J14: -0.39386739 | K14: 1.1129799 | L14: 0.23333333 | M14: 0 | N14: -0.84947435 | O14: 0.044627752 | P14: 11.57 | Q14: -2.5273799
... A145: 45992 | B145: 0.64991632 | C145: 0.32324167 | D145: 0.013241667 | E145: 0.1275 | F145: -0.0025 | G145: 0.015833333 | H145: 0.0025 | I145: 0.017714206 | J145: 0.22777557 | K145: 0.045576251 | L145: 0.25 | M145: -0.0091666667 | N145: -0.59209124 | O145: -0.27306595 | P145: 14.95 | Q145: -7.0273632

Sheet Factor Graphs

Sheet Correlations
B1: slope | C1: butterfly | D1: SONIA | E1: SONIA_EFFR | F1: swap_spread | G1: slope_change | H1: butterfly_change | I1: IG_gilt | J1: HY_IG | K1: S&P_500_HY | L1: inflation | M1: inflation_change | N1: VIX | O1: VIX_change | P1: S&P_500_ERP
A2: slope | B2: 1 | C2: {=TRANSPOSE(B3:B16)} -> 0.88765444 | D2: -0.42088749 | E2: 0.39648998 | F2: 0.59008431 | G2: 0.076139492 | H2: 0.0067948388 | I2: 0.11856944 | J2: -0.043149024 | K2: -0.084023864 | L2: -0.57446258 | M2: 0.01185625 | N2: -0.32924267 | O2: -0.00028365185 | P2: 0.52629534
A3: butterfly | B3: 0.88765444 | C3: 1 | D3: {=TRANSPOSE(C4:C16)} -> -0.58977738 | E3: 0.3821994 | F3: 0.36547352 | G3: -0.021590024 | H3: 0.089079202 | I3: -0.0077315377 | J3: 0.027908517 | K3: 0.0055626168 | L3: -0.40386373 | M3: 0.0047999559 | N3: -0.22136101 | O3: 0.057750646 | P3: 0.68689314
A4: SONIA | B4: -0.42088749 | C4: -0.58977738 | D4: 1 | E4: {=TRANSPOSE(D5:D16)} -> 0.0030457154 | F4: -0.041698491 | G4: 0.12824121 | H4: 0.074361543 | I4: -0.00045154313 | J4: 0.03363418 | K4: -0.092001156 | L4: 0.34826079 | M4: -0.066594349 | N4: -0.12229129 | O4: -0.13237294 | P4: -0.96190474
A5: SONIA_EFFR | B5: 0.39648998 | C5: 0.3821994 | D5: 0.0030457154 | E5: 1 | F5: {=TRANSPOSE(E6:E16)} -> 0.338674 | G5: 0.070058823 | H5: 0.10335938 | I5: 0.045050065 | J5: -0.0073004133 | K5: -0.054346173 | L5: -0.093086024 | M5: 0.068835111 | N5: 0.062283554 | O5: -0.00016740123 | P5: 0.26771107
A6: swap_spread | B6: 0.59008431 | C6: 0.36547352 | D6: -0.041698491 | E6: 0.338674 | F6: 1 | G6: {=TRANSPOSE(F7:F16)} -> 0.03636016 | H6: 0.10724011 | I6: 0.16740175 | J6: -0.076251268 | K6: -0.1197923 | L6: -0.5138289 | M6: 0.089093567 | N6: -0.20565518 | O6: -0.02566677 | P6: 0.1245407
A7: slope_change | B7: 0.076139492 | C7: -0.021590024 | D7: 0.12824121 | E7: 0.070058823 | F7: 0.03636016 | G7: 1 | H7: {=TRANSPOSE(G8:G16)} -> 0.35213338 | I7: 0.083767808 | J7: -0.017240978 | K7: -0.09359429 | L7: 0.0017634481 | M7: -0.12403777 | N7: 0.071774903 | O7: -0.0078739406 | P7: -0.10790789
A8: butterfly_change | B8: 0.0067948388 | C8: 0.089079202 | D8: 0.074361543 | E8: 0.10335938 | F8: 0.10724011 | G8: 0.35213338 | H8: 1 | I8: {=TRANSPOSE(H9:H16)} -> -0.38753107 | J8: 0.39119362 | K8: 0.080504394 | L8: 0.075107542 | M8: 0.056238698 | N8: 0.10334057 | O8: 0.08075058 | P8: -0.050038537
A9: IG_gilt | B9: 0.11856944 | C9: -0.0077315377 | D9: -0.00045154313 | E9: 0.045050065 | F9: 0.16740175 | G9: 0.083767808 | H9: -0.38753107 | I9: 1 | J9: {=TRANSPOSE(I10:I16)} -> -0.60714343 | K9: -0.61796775 | L9: -0.27183892 | M9: -0.12229891 | N9: -0.28397382 | O9: -0.29446414 | P9: 0.011111068
A10: HY_IG | B10: -0.043149024 | C10: 0.027908517 | D10: 0.03363418 | E10: -0.0073004133 | F10: -0.076251268 | G10: -0.017240978 | H10: 0.39119362 | I10: -0.60714343 | J10: 1 | K10: {=TRANSPOSE(J11:J16)} -> -0.24735776 | L10: 0.19477554 | M10: 0.24325704 | N10: -0.082519843 | O10: -0.17278794 | P10: -0.036659792
A11: S&P_500_HY | B11: -0.084023864 | C11: 0.0055626168 | D11: -0.092001156 | E11: -0.054346173 | F11: -0.1197923 | G11: -0.09359429 | H11: 0.080504394 | I11: -0.61796775 | J11: -0.24735776 | K11: 1 | L11: {=TRANSPOSE(K12:K16)} -> 0.11807155 | M11: -0.079919181 | N11: 0.43386126 | O11: 0.5370128 | P11: 0.077368666
A12: inflation | B12: -0.57446258 | C12: -0.40386373 | D12: 0.34826079 | E12: -0.093086024 | F12: -0.5138289 | G12: 0.0017634481 | H12: 0.075107542 | I12: -0.27183892 | J12: 0.19477554 | K12: 0.11807155 | L12: 1 | M12: {=TRANSPOSE(L13:L16)} -> 0.18640677 | N12: 0.20575498 | O12: -0.008406068 | P12: -0.36589067
A13: inflation_change | B13: 0.01185625 | C13: 0.0047999559 | D13: -0.066594349 | E13: 0.068835111 | F13: 0.089093567 | G13: -0.12403777 | H13: 0.056238698 | I13: -0.12229891 | J13: 0.24325704 | K13: -0.079919181 | L13: 0.18640677 | M13: 1 | N13: {=TRANSPOSE(M14:M16)} -> -0.055902789 | O13: 0.015662513 | P13: 0.078080711
A14: VIX | B14: -0.32924267 | C14: -0.22136101 | D14: -0.12229129 | E14: 0.062283554 | F14: -0.20565518 | G14: 0.071774903 | H14: 0.10334057 | I14: -0.28397382 | J14: -0.082519843 | K14: 0.43386126 | L14: 0.20575498 | M14: -0.055902789 | N14: 1 | O14: {=TRANSPOSE(N15:N16)} -> 0.47112813 | P14: 0.12380706
A15: VIX_change | B15: -0.00028365185 | C15: 0.057750646 | D15: -0.13237294 | E15: -0.00016740123 | F15: -0.02566677 | G15: -0.0078739406 | H15: 0.08075058 | I15: -0.29446414 | J15: -0.17278794 | K15: 0.5370128 | L15: -0.008406068 | M15: 0.015662513 | N15: 0.47112813 | O15: 1 | P15: =O16 -> 0.12804606
A16: S&P_500_ERP | B16: 0.52629534 | C16: 0.68689314 | D16: -0.96190474 | E16: 0.26771107 | F16: 0.1245407 | G16: -0.10790789 | H16: -0.050038537 | I16: 0.011111068 | J16: -0.036659792 | K16: 0.077368666 | L16: -0.36589067 | M16: 0.078080711 | N16: 0.12380706 | O16: 0.12804606 | P16: 1

Sheet Full
A1: SUMMARY OUTPUT
A3: Regression Statistics
A4: Multiple R | B4: 0.8252773
A5: R Square | B5: 0.68108262
A6: Adjusted R Square | B6: 0.66466775
A7: Standard Error | B7: 1.0820806
A8: Observations | B8: 144
A10: ANOVA
B11: df | C11: SS | D11: MS | E11: F | F11: Significance F
A12: Regression | B12: 7 | C12: 340.07893 | D12: 48.582705 | E12: 41.491819 | F12: 8.4670326e-31
A13: Residual | B13: 136 | C13: 159.24218 | D13: 1.1708984
A14: Total | B14: 143 | C14: 499.32112
B16: Coefficients | C16: Standard Error | D16: t Stat | E16: P-value | F16: Lower 95% | G16: Upper 95% | H16: Lower 95.0% | I16: Upper 95.0%
A17: Intercept | B17: 0.55203172 | C17: 0.47502652 | D17: 1.1621072 | E17: 0.24722726 | F17: -0.3873621 | G17: 1.4914255 | H17: -0.3873621 | I17: 1.4914255
A18: Average SONIA (%) | B18: 4.4063376 | C18: 2.3066898 | D18: 1.9102428 | E18: 0.058207099 | F18: -0.15528165 | G18: 8.9679568 | H18: -0.15528165 | I18: 8.9679568
A19: 3Y Gilt - 3Y OIS (%) | B19: 0.59779691 | C19: 6.5626442 | D19: 0.091090861 | E19: 0.92755442 | F19: -12.380231 | G19: 13.575825 | H19: -12.380231 | I19: 13.575825
A20: Slope (20Y-3Y) (%) | B20: -3.5214093 | C20: 4.6306672 | D20: -0.76045399 | E20: 0.44829964 | F20: -12.678835 | G20: 5.6360165 | H20: -12.678835 | I20: 5.6360165
A21: Butterfly (2x10Y-20Y-3Y) (%) | B21: 1.8813566 | C21: 7.054118 | D21: 0.26670331 | E21: 0.79010157 | F21: -12.06859 | G21: 15.831304 | H21: -12.06859 | I21: 15.831304
A22: IG Credit Spread (%) | B22: 0.80308412 | C22: 0.04911537 | D22: 16.350974 | E22: 6.5468673e-34 | F22: 0.70595549 | G22: 0.90021275 | H22: 0.70595549 | I22: 0.90021275
A23: HY-IG Spread (%) | B23: 0.47337406 | C23: 0.059477259 | D23: 7.9589083 | E23: 6.0869841e-13 | F23: 0.35575416 | G23: 0.59099395 | H23: 0.35575416 | I23: 0.59099395
A24: S&P 500 ERP GBP Hedged (%) | B24: 4.0352191 | C24: 2.4181279 | D24: 1.6687368 | E24: 0.09747012 | F24: -0.74677583 | G24: 8.817214 | H24: -0.74677583 | I24: 8.817214
A28: RESIDUAL OUTPUT | E28: PROBABILITY OUTPUT
A30: Observation | B30: Predicted Asset Returns (%) | C30: Residuals | E30: Percentile | F30: Asset Returns (%)
A31: 1 | B31: -1.0725037 | C31: -2.0506475 | E31: 0.34722222 | F31: -7.0047285
A32: 2 | B32: 2.0684974 | C32: 1.3703167 | E32: 1.0416667 | F32: -4.6868599
A33: 3 | B33: -0.44858435 | C33: -1.3937333 | E33: 1.7361111 | F33: -4.1526948
A34: 4 | B34: 1.1009437 | C34: -0.33617845 | E34: 2.4305556 | F34: -3.6875242
A35: 5 | B35: 2.0870933 | C35: 0.75676132 | E35: 3.125 | F35: -3.3442886
A36: 6 | B36: -0.21742261 | C36: -0.18845143 | E36: 3.8194444 | F36: -3.1231512
A37: 7 | B37: 0.3556298 | C37: 0.039008105 | E37: 4.5138889 | F37: -2.9682787
A38: 8 | B38: 1.2121348 | C38: -2.0570023 | E38: 5.2083333 | F38: -2.5680571
A39: 9 | B39: 1.2552577 | C39: 0.87680398 | E39: 5.9027778 | F39: -2.5280473
A40: 10 | B40: 0.19844007 | C40: -0.62258018 | E40: 6.5972222 | F40: -2.5046977
A41: 11 | B41: 1.0063524 | C41: -0.26115203 | E41: 7.2916667 | F41: -2.2568119
A42: 12 | B42: 0.9177914 | C42: 0.47159224 | E42: 7.9861111 | F42: -1.9001782
... A174: 144 | B174: 0.6703582 | C174: -0.020441881 | E174: 99.652778 | F174: 5.5867023

Sheet SONIA, Credit, ERP
A1: SUMMARY OUTPUT
A3: Regression Statistics
A4: Multiple R | B4: 0.82309951
A5: R Square | B5: 0.6774928
A6: Adjusted R Square | B6: 0.66821202
A7: Standard Error | B7: 1.0763469
A8: Observations | B8: 144
A10: ANOVA
B11: df | C11: SS | D11: MS | E11: F | F11: Significance F
A12: Regression | B12: 4 | C12: 338.28646 | D12: 84.571615 | E12: 72.999533 | F12: 3.3535557e-33
A13: Residual | B13: 139 | C13: 161.03465 | D13: 1.1585227
A14: Total | B14: 143 | C14: 499.32112
B16: Coefficients | C16: Standard Error | D16: t Stat | E16: P-value | F16: Lower 95% | G16: Upper 95% | H16: Lower 95.0% | I16: Upper 95.0%
A17: Intercept | B17: 0.20325207 | C17: 0.12636649 | D17: 1.6084333 | E17: 0.11000931 | F17: -0.04659694 | G17: 0.45310108 | H17: -0.04659694 | I17: 0.45310108
A18: Average SONIA (%) | B18: 3.4779845 | C18: 2.1114949 | D18: 1.6471669 | E18: 0.10178264 | F18: -0.69681618 | G18: 7.6527853 | H18: -0.69681618 | I18: 7.6527853
A19: IG Credit Spread (%) | B19: 0.79275462 | C19: 0.047520535 | D19: 16.682359 | E19: 5.4247509e-35 | F19: 0.69879808 | G19: 0.88671117 | H19: 0.69879808 | I19: 0.88671117
A20: HY-IG Spread (%) | B20: 0.46943391 | C20: 0.059000873 | D20: 7.9563893 | E20: 5.5926108e-13 | F20: 0.3527787 | G20: 0.58608913 | H20: 0.3527787 | I20: 0.58608913
A21: S&P 500 ERP GBP Hedged (%) | B21: 2.8510881 | C21: 2.0088892 | D21: 1.4192361 | E21: 0.15806879 | F21: -1.1208429 | G21: 6.8230192 | H21: -1.1208429 | I21: 6.8230192
A25: RESIDUAL OUTPUT | E25: PROBABILITY OUTPUT
A27: Observation | B27: Predicted Asset Returns (%) | C27: Residuals | E27: Percentile | F27: Asset Returns (%)
A28: 1 | B28: -0.81907249 | C28: -2.3040787 | E28: 0.34722222 | F28: -7.0047285
A29: 2 | B29: 2.3118429 | C29: 1.1269712 | E29: 1.0416667 | F29: -4.6868599
A30: 3 | B30: -0.24408888 | C30: -1.5982288 | E30: 1.7361111 | F30: -4.1526948
A31: 4 | B31: 1.2594681 | C31: -0.49470288 | E31: 2.4305556 | F31: -3.6875242
A32: 5 | B32: 2.2335577 | C32: 0.61029692 | E32: 3.125 | F32: -3.3442886
A33: 6 | B33: -0.034783334 | C33: -0.3710907 | E33: 3.8194444 | F33: -3.1231512
A34: 7 | B34: 0.44590558 | C34: -0.051267674 | E34: 4.5138889 | F34: -2.9682787
A35: 8 | B35: 1.3233839 | C35: -2.1682514 | E35: 5.2083333 | F35: -2.5680571
A36: 9 | B36: 1.3625179 | C36: 0.76954369 | E36: 5.9027778 | F36: -2.5280473
A37: 10 | B37: 0.29895281 | C37: -0.72309291 | E37: 6.5972222 | F37: -2.5046977
A38: 11 | B38: 1.0904995 | C38: -0.3452991 | E38: 7.2916667 | F38: -2.2568119
A39: 12 | B39: 1.0009515 | C39: 0.38843212 | E39: 7.9861111 | F39: -1.9001782
... A171: 144 | B171: 0.75091168 | C171: -0.10099536 | E171: 99.652778 | F171: 5.5867023

Sheet SONIA, Credit, ERP, Inflation
A1: SUMMARY OUTPUT
A3: Regression Statistics
A4: Multiple R | B4: 0.82890226
A5: R Square | B5: 0.68707895
A6: Adjusted R Square | B6: 0.67574123
A7: Standard Error | B7: 1.0640641
A8: Observations | B8: 144
A10: ANOVA
B11: df | C11: SS | D11: MS | E11: F | F11: Significance F
A12: Regression | B12: 5 | C12: 343.07303 | D12: 68.614606 | E12: 60.601162 | F12: 3.9000241e-33
A13: Residual | B13: 138 | C13: 156.24809 | D13: 1.1322325
A14: Total | B14: 143 | C14: 499.32112
B16: Coefficients | C16: Standard Error | D16: t Stat | E16: P-value | F16: Lower 95% | G16: Upper 95% | H16: Lower 95.0% | I16: Upper 95.0%
A17: Intercept | B17: -0.71713677 | C17: 0.46474297 | D17: -1.5430825 | E17: 0.12510081 | F17: -1.6360747 | G17: 0.20180116 | H17: -1.6360747 | I17: 0.20180116
A18: Average SONIA (%) | B18: 3.4971559 | C18: 2.0874203 | D18: 1.6753482 | E18: 0.096130399 | F18: -0.63030771 | G18: 7.6246196 | H18: -0.63030771 | I18: 7.6246196
A19: IG Credit Spread (%) | B19: 0.81421953 | C19: 0.048124234 | D19: 16.919117 | E19: 1.8216166e-35 | F19: 0.71906331 | G19: 0.90937575 | H19: 0.71906331 | I19: 0.90937575
A20: HY-IG Spread (%) | B20: 0.46622379 | C20: 0.058348474 | D20: 7.9903339 | E20: 4.7867554e-13 | F20: 0.35085114 | G20: 0.58159643 | H20: 0.35085114 | I20: 0.58159643
A21: S&P 500 ERP GBP Hedged (%) | B21: 3.3218485 | C21: 1.9991192 | D21: 1.661656 | E21: 0.098851818 | F21: -0.631017 | G21: 7.274714 | H21: -0.631017 | I21: 7.274714
A22: Inflation (3Y gilt - 3Y IL) (%) | B22: 3.6183958 | C22: 1.7598344 | D22: 2.0561001 | E22: 0.041657537 | F22: 0.13866889 | G22: 7.0981226 | H22: 0.13866889 | I22: 7.0981226
A26: RESIDUAL OUTPUT | E26: PROBABILITY OUTPUT
A28: Observation | B28: Predicted Asset Returns (%) | C28: Residuals | E28: Percentile | F28: Asset Returns (%)
A29: 1 | B29: -1.1306068 | C29: -1.9925444 | E29: 0.34722222 | F29: -7.0047285
A30: 2 | B30: 2.252095 | C30: 1.1867191 | E30: 1.0416667 | F30: -4.6868599
A31: 3 | B31: -0.33742676 | C31: -1.5048909 | E31: 1.7361111 | F31: -4.1526948
A32: 4 | B32: 1.2059128 | C32: -0.44114756 | E32: 2.4305556 | F32: -3.6875242
A33: 5 | B33: 2.2323922 | C33: 0.61146246 | E33: 3.125 | F33: -3.3442886
A34: 6 | B34: -0.13992816 | C34: -0.26594588 | E34: 3.8194444 | F34: -3.1231512
A35: 7 | B35: 0.39320629 | C35: 0.0014316166 | E35: 4.5138889 | F35: -2.9682787
A36: 8 | B36: 1.2881955 | C36: -2.133063 | E36: 5.2083333 | F36: -2.5680571
A37: 9 | B37: 1.3093474 | C37: 0.82271429 | E37: 5.9027778 | F37: -2.5280473
A38: 10 | B38: 0.25385622 | C38: -0.67799632 | E38: 6.5972222 | F38: -2.5046977
A39: 11 | B39: 1.1079698 | C39: -0.36276942 | E39: 7.2916667 | F39: -2.2568119
A40: 12 | B40: 0.97387455 | C40: 0.41550908 | E40: 7.9861111 | F40: -1.9001782
... A172: 144 | B172: 0.61751303 | C172: 0.032403292 | E172: 99.652778 | F172: 5.5867023

Sheet Credit, ERP, Inflation
A1: SUMMARY OUTPUT
A3: Regression Statistics
A4: Multiple R | B4: 0.8250542
A5: R Square | B5: 0.68071443
A6: Adjusted R Square | B6: 0.67152635
A7: Standard Error | B7: 1.0709574
A8: Observations | B8: 144
A10: ANOVA
B11: df | C11: SS | D11: MS | E11: F | F11: Significance F
A12: Regression | B12: 4 | C12: 339.89509 | D12: 84.973772 | E12: 74.086738 | F12: 1.6768523e-33
A13: Residual | B13: 139 | C13: 159.42603 | D13: 1.1469498
A14: Total | B14: 143 | C14: 499.32112
B16: Coefficients | C16: Standard Error | D16: t Stat | E16: P-value | F16: Lower 95% | G16: Upper 95% | H16: Lower 95.0% | I16: Upper 95.0%
A17: Intercept | B17: -0.59942015 | C17: 0.46237682 | D17: -1.2963888 | E17: 0.19698973 | F17: -1.5136213 | G17: 0.314781 | H17: -1.5136213 | I17: 0.314781
A18: IG Credit Spread (%) | B18: 0.81749189 | C18: 0.048396084 | D18: 16.891695 | E18: 1.6924135e-35 | F18: 0.72180423 | G18: 0.91317955 | H18: 0.72180423 | I18: 0.91317955
A19: HY-IG Spread (%) | B19: 0.46829973 | C19: 0.058713227 | D19: 7.9760516 | E19: 5.0142596e-13 | F19: 0.35221324 | G19: 0.58438621 | H19: 0.35221324 | I19: 0.58438621
A20: S&P 500 ERP GBP Hedged (%) | B20: 0.11972347 | C20: 0.58974552 | D20: 0.2030087 | E20: 0.8394251 | F20: -1.0463082 | G20: 1.2857552 | H20: -1.0463082 | I20: 1.2857552
A21: Inflation (3Y gilt - 3Y IL) (%) | B21: 3.605226 | C21: 1.7712174 | D21: 2.0354508 | E21: 0.04370576 | F21: 0.10321436 | G21: 7.1072377 | H21: 0.10321436 | I21: 7.1072377
A25: RESIDUAL OUTPUT | F25: PROBABILITY OUTPUT
A27: Observation | B27: Predicted Asset Returns (%) | C27: Residuals | D27: Standard Residuals | F27: Percentile | G27: Asset Returns (%)
A28: 1 | B28: -1.2997818 | C28: -1.8233694 | D28: -1.7268836 | F28: 0.34722222 | G28: -7.0047285
A29: 2 | B29: 2.0965266 | C29: 1.3422876 | D29: 1.2712588 | F29: 1.0416667 | G29: -4.6868599
A30: 3 | B30: -0.50748238 | C30: -1.3348353 | D30: -1.2642009 | F30: 1.7361111 | G30: -4.1526948
A31: 4 | B31: 1.0408832 | C31: -0.2761179 | D31: -0.26150679 | F31: 2.4305556 | G31: -3.6875242
A32: 5 | B32: 2.0733634 | C32: 0.77049126 | D32: 0.72971979 | F32: 3.125 | G32: -3.3442886
A33: 6 | B33: -0.30747921 | C33: -0.098394832 | D33: -0.093188151 | F33: 3.8194444 | G33: -3.1231512
A34: 7 | B34: 0.23159351 | C34: 0.1630444 | D34: 0.1544167 | F34: 4.5138889 | G34: -2.9682787
A35: 8 | B35: 1.1235542 | C35: -1.9684216 | D35: -1.8642602 | F35: 5.2083333 | G35: -2.5680571
A36: 9 | B36: 1.1469334 | C36: 0.98512828 | D36: 0.93299903 | F36: 5.9027778 | G36: -2.5280473
A37: 10 | B37: 0.094657117 | C37: -0.51879722 | D37: -0.49134444 | F37: 6.5972222 | G37: -2.5046977
A38: 11 | B38: 0.95147372 | C38: -0.20627336 | D38: -0.19535816 | F38: 7.2916667 | G38: -2.2568119
A39: 12 | B39: 0.81785778 | C39: 0.57152586 | D39: 0.54128288 | F39: 7.9861111 | G39: -1.9001782
... A171: 144 | B171: 0.47674198 | C171: 0.17317434 | D171: 0.16401061 | F171: 99.652778 | G171: 5.5867023

Sheet SONIA, Credit, Inflation
A1: SUMMARY OUTPUT
A3: Regression Statistics
A4: Multiple R | B4: 0.82511698
A5: R Square | B5: 0.68081803
A6: Adjusted R Square | B6: 0.67163294
A7: Standard Error | B7: 1.0707837
A8: Observations | B8: 144
A10: ANOVA
B11: df | C11: SS | D11: MS | E11: F | F11: Significance F
A12: Regression | B12: 4 | C12: 339.94682 | D12: 84.986705 | E12: 74.122066 | F12: 1.639697e-33
A13: Residual | B13: 139 | C13: 159.3743 | D13: 1.1465777
A14: Total | B14: 143 | C14: 499.32112
B16: Coefficients | C16: Standard Error | D16: t Stat | E16: P-value | F16: Lower 95% | G16: Upper 95% | H16: Lower 95.0% | I16: Upper 95.0%
A17: Intercept | B17: -0.54832066 | C17: 0.45636629 | D17: -1.2014925 | E17: 0.23160338 | F17: -1.4506379 | G17: 0.3539966 | H17: -1.4506379 | I17: 0.3539966
A18: Average SONIA (%) | B18: 0.18091902 | C18: 0.61569468 | D18: 0.29384536 | E18: 0.76931438 | F18: -1.0364188 | G18: 1.3982568 | H18: -1.0364188 | I18: 1.3982568
A19: IG Credit Spread (%) | B19: 0.81511097 | C19: 0.048425127 | D19: 16.832397 | E19: 2.3527801e-35 | F19: 0.71936589 | G19: 0.91085606 | H19: 0.71936589 | I19: 0.91085606
A20: HY-IG Spread (%) | B20: 0.46748662 | C20: 0.058711961 | D20: 7.9623745 | E20: 5.4098829e-13 | F20: 0.35140264 | G20: 0.58357061 | H20: 0.35140264 | I20: 0.58357061
A21: Inflation (3Y gilt - 3Y IL) (%) | B21: 3.2834844 | C21: 1.7592946 | D21: 1.8663641 | E21: 0.064097449 | F21: -0.19495376 | G21: 6.7619226 | H21: -0.19495376 | I21: 6.7619226
A25: RESIDUAL OUTPUT | F25: PROBABILITY OUTPUT
A27: Observation | B27: Predicted Asset Returns (%) | C27: Residuals | D27: Standard Residuals | F27: Percentile | G27: Asset Returns (%)
A28: 1 | B28: -1.3042411 | C28: -1.8189101 | D28: -1.7229399 | F28: 0.34722222 | G28: -7.0047285
A29: 2 | B29: 2.0728548 | C29: 1.3659593 | D29: 1.2938879 | F29: 1.0416667 | G29: -4.6868599
A30: 3 | B30: -0.52686428 | C30: -1.3154534 | D30: -1.2460468 | F30: 1.7361111 | G30: -4.1526948
A31: 4 | B31: 1.0169002 | C31: -0.25213491 | D31: -0.23883164 | F31: 2.4305556 | G31: -3.6875242
A32: 5 | B32: 2.0441803 | C32: 0.7996743 | D32: 0.75748148 | F32: 3.125 | G32: -3.3442886
A33: 6 | B33: -0.32687206 | C33: -0.07900198 | D33: -0.074833638 | F33: 3.8194444 | G33: -3.1231512
A34: 7 | B34: 0.20702206 | C34: 0.18761584 | D34: 0.17771676 | F34: 4.5138889 | G34: -2.9682787
A35: 8 | B35: 1.099512 | C35: -1.9443795 | D35: -1.8417892 | F35: 5.2083333 | G35: -2.5680571
A36: 9 | B36: 1.121613 | C36: 1.0104487 | D36: 0.95713485 | F36: 5.9027778 | G36: -2.5280473
A37: 10 | B37: 0.070516047 | C37: -0.49465615 | D37: -0.46855685 | F37: 6.5972222 | G37: -2.5046977
A38: 11 | B38: 0.92215678 | C38: -0.17695642 | D38: -0.16761976 | F38: 7.2916667 | G38: -2.2568119
A39: 12 | B39: 0.79261274 | C39: 0.59677089 | D39: 0.56528376 | F39: 7.9861111 | G39: -1.9001782
... A171: 144 | B171: 0.53799966 | C171: 0.11191666 | D171: 0.10601166 | F171: 99.652778 | G171: 5.5867023

Sheet Credit, Inflation
A1: SUMMARY OUTPUT
A3: Regression Statistics
A4: Multiple R | B4: 0.82499683
A5: R Square | B5: 0.68061976
A6: Adjusted R Square | B6: 0.6737759
A7: Standard Error | B7: 1.0672839
A8: Observations | B8: 144
A10: ANOVA
B11: df | C11: SS | D11: MS | E11: F | F11: Significance F
A12: Regression | B12: 3 | C12: 339.84782 | D12: 113.28261 | E12: 99.449659 | F12: 1.5731236e-34
A13: Residual | B13: 140 | C13: 159.4733 | D13: 1.139095
A14: Total | B14: 143 | C14: 499.32112
B16: Coefficients | C16: Standard Error | D16: t Stat | E16: P-value | F16: Lower 95% | G16: Upper 95% | H16: Lower 95.0% | I16: Upper 95.0%
A17: Intercept | B17: -0.57542787 | C17: 0.44548455 | D17: -1.2916898 | E17: 0.19859296 | F17: -1.4561748 | G17: 0.30531902 | H17: -1.4561748 | I17: 0.30531902
A18: IG Credit Spread (%) | B18: 0.81656406 | C18: 0.048014531 | D18: 17.006603 | E18: 7.1351237e-36 | F18: 0.72163675 | G18: 0.91149137 | H18: 0.72163675 | I18: 0.91149137
A19: HY-IG Spread (%) | B19: 0.46800367 | C19: 0.058493781 | D19: 8.0009132 | E19: 4.2268069e-13 | F19: 0.35235832 | G19: 0.58364901 | H19: 0.35235832 | I19: 0.58364901
A20: Inflation (3Y gilt - 3Y IL) (%) | B20: 3.469962 | C20: 1.6354862 | D20: 2.12167 | E20: 0.035626877 | F20: 0.23651788 | G20: 6.7034062 | H20: 0.23651788 | I20: 6.7034062
A24: RESIDUAL OUTPUT | F24: PROBABILITY OUTPUT
A26: Observation | B26: Predicted Asset Returns (%) | C26: Residuals | D26: Standard Residuals | F26: Percentile | G26: Asset Returns (%)
A27: 1 | B27: -1.3053243 | C27: -1.817827 | D27: -1.7213793 | F27: 0.34722222 | G27: -7.0047285
A28: 2 | B28: 2.0832194 | C28: 1.3555948 | D28: 1.2836716 | F28: 1.0416667 | G28: -4.6868599
A29: 3 | B29: -0.51930431 | C29: -1.3230134 | D29: -1.2528188 | F29: 1.7361111 | G29: -4.1526948
A30: 4 | B30: 1.02724 | C30: -0.26247478 | D30: -0.24854877 | F30: 2.4305556 | G30: -3.6875242
A31: 5 | B31: 2.0576689 | C31: 0.78618568 | D31: 0.74447336 | F31: 3.125 | G31: -3.3442886
A32: 6 | B32: -0.31925137 | C32: -0.086622664 | D32: -0.082026762 | F32: 3.8194444 | G32: -3.1231512
A33: 7 | B33: 0.21777768 | C33: 0.17686023 | D33: 0.16747663 | F33: 4.5138889 | G33: -2.9682787
A34: 8 | B34: 1.1098947 | C34: -1.9547621 | D34: -1.8510492 | F34: 5.2083333 | G34: -2.5680571
A35: 9 | B35: 1.132786 | C35: 0.99927569 | D35: 0.94625754 | F35: 5.9027778 | G35: -2.5280473
A36: 10 | B36: 0.081074224 | C36: -0.50521433 | D36: -0.47840939 | F36: 6.5972222 | G36: -2.5046977
A37: 11 | B37: 0.93577809 | C37: -0.19057774 | D37: -0.18046634 | F37: 7.2916667 | G37: -2.2568119
A38: 12 | B38: 0.80388082 | C38: 0.58550282 | D38: 0.55443805 | F38: 7.9861111 | G38: -1.9001782
... A170: 144 | B170: 0.49938583 | C170: 0.1505305 | D170: 0.14254386 | F170: 99.652778 | G170: 5.5867023

Sheet Credit
A1: SUMMARY OUTPUT
A3: Regression Statistics
A4: Multiple R | B4: 0.8187494
A5: R Square | B5: 0.67035058
A6: Adjusted R Square | B6: 0.66567471
A7: Standard Error | B7: 1.0804547
A8: Observations | B8: 144
A10: ANOVA
B11: df | C11: SS | D11: MS | E11: F | F11: Significance F
A12: Regression | B12: 2 | C12: 334.7202 | D12: 167.3601 | E12: 143.36357 | F12: 1.0536292e-34
A13: Residual | B13: 141 | C13: 164.60091 | D13: 1.1673824
A14: Total | B14: 143 | C14: 499.32112
B16: Coefficients | C16: Standard Error | D16: t Stat | E16: P-value | F16: Lower 95% | G16: Upper 95% | H16: Lower 95.0% | I16: Upper 95.0%
A17: Intercept | B17: 0.35054132 | C17: 0.09044305 | D17: 3.8758238 | E17: 0.00016225787 | F17: 0.17174161 | G17: 0.52934103 | H17: 0.17174161 | I17: 0.52934103
A18: IG Credit Spread (%) | B18: 0.79648952 | C18: 0.047653953 | D18: 16.714028 | E18: 2.9410422e-35 | F18: 0.70228092 | G18: 0.89069812 | H18: 0.70228092 | I18: 0.89069812
A19: HY-IG Spread (%) | B19: 0.47282884 | C19: 0.059170848 | D19: 7.9909087 | E19: 4.3275242e-13 | F19: 0.35585213 | G19: 0.58980555 | H19: 0.35585213 | I19: 0.58980555
A23: RESIDUAL OUTPUT | F23: PROBABILITY OUTPUT
A25: Observation | B25: Predicted Asset Returns (%) | C25: Residuals | D25: Standard Residuals | F25: Percentile | G25: Asset Returns (%)
A26: 1 | B26: -0.93284394 | C26: -2.1903073 | D26: -2.0415355 | F26: 0.34722222 | G26: -7.0047285
A27: 2 | B27: 2.2071863 | C27: 1.2316279 | D27: 1.1479723 | F27: 1.0416667 | G27: -4.6868599
A28: 3 | B28: -0.36400685 | C28: -1.4783108 | D28: -1.3778999 | F28: 1.7361111 | G28: -4.1526948
A29: 4 | B29: 1.1457677 | C29: -0.38100242 | D29: -0.35512368 | F29: 2.4305556 | G29: -3.6875242
A30: 5 | B30: 2.1263107 | C30: 0.71754394 | D30: 0.66880637 | F30: 3.125 | G30: -3.3442886
A31: 6 | B31: -0.15099042 | C31: -0.25488362 | D31: -0.23757122 | F31: 3.8194444 | G31: -3.1231512
A32: 7 | B32: 0.33605849 | C32: 0.058579412 | D32: 0.054600536 | F32: 4.5138889 | G32: -2.9682787
A33: 8 | B33: 1.207972 | C33: -2.0528395 | D33: -1.9134049 | F33: 5.2083333 | G33: -2.5680571
A34: 9 | B34: 1.2530003 | C34: 0.87906135 | D34: 0.81935306 | F34: 5.9027778 | G34: -2.5280473
A35: 10 | B35: 0.18986245 | C35: -0.61400256 | D35: -0.5722978 | F35: 6.5972222 | G35: -2.5046977
A36: 11 | B36: 0.98359173 | C36: -0.23839137 | D36: -0.22219917 | F36: 7.2916667 | G36: -2.2568119
A37: 12 | B37: 0.89418665 | C37: 0.49519699 | D37: 0.46156184 | F37: 7.9861111 | G37: -1.9001782
... A169: 144 | B169: 0.55351194 | C169: 0.09640438 | D169: 0.089856327 | F169: 99.652778 | G169: 5.5867023

Sheet Credit, SP-HY
A1: SUMMARY OUTPUT
A3: Regression Statistics
A4: Multiple R | B4: 0.81889597
A5: R Square | B5: 0.67059061
A6: Adjusted R Square | B6: 0.66353183
A7: Standard Error | B7: 1.0839118
A8: Observations | B8: 144
A10: ANOVA
B11: df | C11: SS | D11: MS | E11: F | F11: Significance F
A12: Regression | B12: 3 | C12: 334.84005 | D12: 111.61335 | E12: 95.00102 | F12: 1.3600711e-33
A13: Residual | B13: 140 | C13: 164.48107 | D13: 1.1748648
A14: Total | B14: 143 | C14: 499.32112
B16: Coefficients | C16: Standard Error | D16: t Stat | E16: P-value | F16: Lower 95% | G16: Upper 95% | H16: Lower 95.0% | I16: Upper 95.0%
A17: Intercept | B17: 0.31831478 | C17: 0.13569539 | D17: 2.3458038 | E17: 0.020389637 | F17: 0.050037691 | G17: 0.58659186 | H17: 0.050037691 | I17: 0.58659186
A18: IG Credit Spread (%) | B18: 0.57043507 | C18: 0.70938192 | D18: 0.80412969 | E18: 0.42268541 | F18: -0.83205111 | G18: 1.9729212 | H18: -0.83205111 | I18: 1.9729212
A19: HY-IG Spread (%) | B19: 0.24534401 | C19: 0.714717 | D19: 0.34327435 | E19: 0.73190702 | F19: -1.1676899 | G19: 1.6583779 | H19: -1.1676899 | I19: 1.6583779
A20: S&P 500 - HY (%) | B20: -0.22900523 | C20: 0.717008 | D20: -0.31939006 | E20: 0.74990683 | F20: -1.6465686 | G20: 1.1885581 | H20: -1.6465686 | I20: 1.1885581
A24: RESIDUAL OUTPUT | F24: PROBABILITY OUTPUT
